[2023-05-10 04:02:08,483] {taskinstance.py:1032} INFO - Dependencies all met for <TaskInstance: data_processing_dag.process_dataset manual__2023-05-10T03:51:56.264499+00:00 [queued]>
[2023-05-10 04:02:08,538] {taskinstance.py:1032} INFO - Dependencies all met for <TaskInstance: data_processing_dag.process_dataset manual__2023-05-10T03:51:56.264499+00:00 [queued]>
[2023-05-10 04:02:08,538] {taskinstance.py:1238} INFO - 
--------------------------------------------------------------------------------
[2023-05-10 04:02:08,539] {taskinstance.py:1239} INFO - Starting attempt 2 of 3
[2023-05-10 04:02:08,539] {taskinstance.py:1240} INFO - 
--------------------------------------------------------------------------------
[2023-05-10 04:02:08,659] {taskinstance.py:1259} INFO - Executing <Task(PythonOperator): process_dataset> on 2023-05-10 03:51:56.335783+00:00
[2023-05-10 04:02:08,678] {standard_task_runner.py:52} INFO - Started process 2129 to run task
[2023-05-10 04:02:08,711] {standard_task_runner.py:76} INFO - Running: ['***', 'tasks', 'run', 'data_processing_dag', 'process_dataset', 'manual__2023-05-10T03:51:56.264499+00:00', '--job-id', '128', '--raw', '--subdir', 'DAGS_FOLDER/data_processing_dag.py', '--cfg-path', '/tmp/tmpat9bxv5q', '--error-file', '/tmp/tmp5y2_6lqd']
[2023-05-10 04:02:08,713] {standard_task_runner.py:77} INFO - Job 128: Subtask process_dataset
[2023-05-10 04:02:09,230] {logging_mixin.py:109} INFO - Running <TaskInstance: data_processing_dag.process_dataset manual__2023-05-10T03:51:56.264499+00:00 [running]> on host cd79de2e36bd
[2023-05-10 04:02:09,943] {taskinstance.py:1426} INFO - Exporting the following env vars:
AIRFLOW_CTX_DAG_OWNER=***
AIRFLOW_CTX_DAG_ID=data_processing_dag
AIRFLOW_CTX_TASK_ID=process_dataset
AIRFLOW_CTX_EXECUTION_DATE=2023-05-10T03:51:56.335783+00:00
AIRFLOW_CTX_DAG_RUN_ID=manual__2023-05-10T03:51:56.264499+00:00
[2023-05-10 04:02:09,990] {logging_mixin.py:109} WARNING - /home/***/.local/lib/python3.7/site-packages/***/utils/context.py:152 AirflowContextDeprecationWarning: Accessing 'execution_date' from the template is deprecated and will be removed in a future version. Please use 'data_interval_start' or 'logical_date' instead.
[2023-05-10 04:02:10,008] {logging_mixin.py:109} WARNING - /home/***/.local/lib/python3.7/site-packages/***/utils/context.py:152 AirflowContextDeprecationWarning: Accessing 'next_ds' from the template is deprecated and will be removed in a future version. Please use '{{ data_interval_end | ds }}' instead.
[2023-05-10 04:02:10,023] {logging_mixin.py:109} WARNING - /home/***/.local/lib/python3.7/site-packages/***/utils/context.py:152 AirflowContextDeprecationWarning: Accessing 'next_ds_nodash' from the template is deprecated and will be removed in a future version. Please use '{{ data_interval_end | ds_nodash }}' instead.
[2023-05-10 04:02:10,026] {logging_mixin.py:109} WARNING - /home/***/.local/lib/python3.7/site-packages/***/utils/context.py:152 AirflowContextDeprecationWarning: Accessing 'next_execution_date' from the template is deprecated and will be removed in a future version. Please use 'data_interval_end' instead.
[2023-05-10 04:02:10,028] {logging_mixin.py:109} WARNING - /home/***/.local/lib/python3.7/site-packages/***/utils/context.py:152 AirflowContextDeprecationWarning: Accessing 'prev_ds' from the template is deprecated and will be removed in a future version.
[2023-05-10 04:02:10,070] {logging_mixin.py:109} WARNING - /home/***/.local/lib/python3.7/site-packages/***/utils/context.py:152 AirflowContextDeprecationWarning: Accessing 'prev_ds_nodash' from the template is deprecated and will be removed in a future version.
[2023-05-10 04:02:10,075] {logging_mixin.py:109} WARNING - /home/***/.local/lib/python3.7/site-packages/***/utils/context.py:152 AirflowContextDeprecationWarning: Accessing 'prev_execution_date' from the template is deprecated and will be removed in a future version.
[2023-05-10 04:02:10,088] {logging_mixin.py:109} WARNING - /home/***/.local/lib/python3.7/site-packages/***/utils/context.py:152 AirflowContextDeprecationWarning: Accessing 'prev_execution_date_success' from the template is deprecated and will be removed in a future version. Please use 'prev_data_interval_start_success' instead.
[2023-05-10 04:02:10,091] {logging_mixin.py:109} WARNING - /home/***/.local/lib/python3.7/site-packages/***/utils/context.py:152 AirflowContextDeprecationWarning: Accessing 'tomorrow_ds' from the template is deprecated and will be removed in a future version.
[2023-05-10 04:02:10,094] {logging_mixin.py:109} WARNING - /home/***/.local/lib/python3.7/site-packages/***/utils/context.py:152 AirflowContextDeprecationWarning: Accessing 'tomorrow_ds_nodash' from the template is deprecated and will be removed in a future version.
[2023-05-10 04:02:10,165] {logging_mixin.py:109} WARNING - /home/***/.local/lib/python3.7/site-packages/***/utils/context.py:152 AirflowContextDeprecationWarning: Accessing 'yesterday_ds' from the template is deprecated and will be removed in a future version.
[2023-05-10 04:02:10,167] {logging_mixin.py:109} WARNING - /home/***/.local/lib/python3.7/site-packages/***/utils/context.py:152 AirflowContextDeprecationWarning: Accessing 'yesterday_ds_nodash' from the template is deprecated and will be removed in a future version.
[2023-05-10 04:02:10,167] {taskinstance.py:1700} ERROR - Task failed with exception
Traceback (most recent call last):
  File "/home/airflow/.local/lib/python3.7/site-packages/airflow/models/taskinstance.py", line 1329, in _run_raw_task
    self._execute_task_with_callbacks(context)
  File "/home/airflow/.local/lib/python3.7/site-packages/airflow/models/taskinstance.py", line 1455, in _execute_task_with_callbacks
    result = self._execute_task(context, self.task)
  File "/home/airflow/.local/lib/python3.7/site-packages/airflow/models/taskinstance.py", line 1511, in _execute_task
    result = execute_callable(context=context)
  File "/home/airflow/.local/lib/python3.7/site-packages/airflow/operators/python.py", line 174, in execute
    return_value = self.execute_callable()
  File "/home/airflow/.local/lib/python3.7/site-packages/airflow/operators/python.py", line 185, in execute_callable
    return self.python_callable(*self.op_args, **self.op_kwargs)
  File "/opt/airflow/dags/data_processing_dag.py", line 40, in run_callable_multiprocess
    p.start()
  File "/usr/local/lib/python3.7/multiprocessing/process.py", line 110, in start
    'daemonic processes are not allowed to have children'
AssertionError: daemonic processes are not allowed to have children
[2023-05-10 04:02:10,284] {taskinstance.py:1277} INFO - Marking task as UP_FOR_RETRY. dag_id=data_processing_dag, task_id=process_dataset, execution_date=20230510T035156, start_date=20230510T040208, end_date=20230510T040210
[2023-05-10 04:02:10,345] {standard_task_runner.py:92} ERROR - Failed to execute job 128 for task process_dataset
Traceback (most recent call last):
  File "/home/airflow/.local/lib/python3.7/site-packages/airflow/task/task_runner/standard_task_runner.py", line 85, in _start_by_fork
    args.func(args, dag=self.dag)
  File "/home/airflow/.local/lib/python3.7/site-packages/airflow/cli/cli_parser.py", line 48, in command
    return func(*args, **kwargs)
  File "/home/airflow/.local/lib/python3.7/site-packages/airflow/utils/cli.py", line 92, in wrapper
    return f(*args, **kwargs)
  File "/home/airflow/.local/lib/python3.7/site-packages/airflow/cli/commands/task_command.py", line 298, in task_run
    _run_task_by_selected_method(args, dag, ti)
  File "/home/airflow/.local/lib/python3.7/site-packages/airflow/cli/commands/task_command.py", line 107, in _run_task_by_selected_method
    _run_raw_task(args, ti)
  File "/home/airflow/.local/lib/python3.7/site-packages/airflow/cli/commands/task_command.py", line 184, in _run_raw_task
    error_file=args.error_file,
  File "/home/airflow/.local/lib/python3.7/site-packages/airflow/utils/session.py", line 70, in wrapper
    return func(*args, session=session, **kwargs)
  File "/home/airflow/.local/lib/python3.7/site-packages/airflow/models/taskinstance.py", line 1329, in _run_raw_task
    self._execute_task_with_callbacks(context)
  File "/home/airflow/.local/lib/python3.7/site-packages/airflow/models/taskinstance.py", line 1455, in _execute_task_with_callbacks
    result = self._execute_task(context, self.task)
  File "/home/airflow/.local/lib/python3.7/site-packages/airflow/models/taskinstance.py", line 1511, in _execute_task
    result = execute_callable(context=context)
  File "/home/airflow/.local/lib/python3.7/site-packages/airflow/operators/python.py", line 174, in execute
    return_value = self.execute_callable()
  File "/home/airflow/.local/lib/python3.7/site-packages/airflow/operators/python.py", line 185, in execute_callable
    return self.python_callable(*self.op_args, **self.op_kwargs)
  File "/opt/airflow/dags/data_processing_dag.py", line 40, in run_callable_multiprocess
    p.start()
  File "/usr/local/lib/python3.7/multiprocessing/process.py", line 110, in start
    'daemonic processes are not allowed to have children'
AssertionError: daemonic processes are not allowed to have children
[2023-05-10 04:02:10,400] {local_task_job.py:154} INFO - Task exited with return code 1
[2023-05-10 04:02:10,507] {local_task_job.py:264} INFO - 0 downstream tasks scheduled from follow-on schedule check
